Traceback (most recent call last):
  File "/Users/josh/opt/anaconda3/envs/jupyter_book/lib/python3.7/site-packages/jupyter_cache/executors/utils.py", line 56, in single_nb_execution
    record_timing=False,
  File "/Users/josh/opt/anaconda3/envs/jupyter_book/lib/python3.7/site-packages/nbclient/client.py", line 1112, in execute
    return NotebookClient(nb=nb, resources=resources, km=km, **kwargs).execute()
  File "/Users/josh/opt/anaconda3/envs/jupyter_book/lib/python3.7/site-packages/nbclient/util.py", line 74, in wrapped
    return just_run(coro(*args, **kwargs))
  File "/Users/josh/opt/anaconda3/envs/jupyter_book/lib/python3.7/site-packages/nbclient/util.py", line 53, in just_run
    return loop.run_until_complete(coro)
  File "/Users/josh/opt/anaconda3/envs/jupyter_book/lib/python3.7/asyncio/base_events.py", line 587, in run_until_complete
    return future.result()
  File "/Users/josh/opt/anaconda3/envs/jupyter_book/lib/python3.7/site-packages/nbclient/client.py", line 554, in async_execute
    cell, index, execution_count=self.code_cells_executed + 1
  File "/Users/josh/opt/anaconda3/envs/jupyter_book/lib/python3.7/site-packages/nbclient/client.py", line 857, in async_execute_cell
    self._check_raise_for_error(cell, exec_reply)
  File "/Users/josh/opt/anaconda3/envs/jupyter_book/lib/python3.7/site-packages/nbclient/client.py", line 760, in _check_raise_for_error
    raise CellExecutionError.from_cell_and_msg(cell, exec_reply_content)
nbclient.exceptions.CellExecutionError: An error occurred while executing the following cell:
------------------
import matplotlib.pyplot as plt  
from sklearn.datasets import make_classification
from sklearn.metrics import plot_confusion_matrix
from sklearn.model_selection import train_test_split
from sklearn.svm import SVC
X, y = make_classification(random_state=0)
X_train, X_test, y_train, y_test = train_test_split(
        X, y, random_state=0)
clf = SVC(random_state=0)
clf.fit(X_train, y_train)

plot_confusion_matrix(clf, X_test, y_test)  
plt.show()  
------------------

[0;31m---------------------------------------------------------------------------[0m
[0;31mModuleNotFoundError[0m                       Traceback (most recent call last)
[0;32m/var/folders/wd/5mwvr_hx3p5436myvcwcvk6w0000gn/T/ipykernel_30228/2866369948.py[0m in [0;36m<module>[0;34m[0m
[0;32m----> 1[0;31m [0;32mimport[0m [0mmatplotlib[0m[0;34m.[0m[0mpyplot[0m [0;32mas[0m [0mplt[0m[0;34m[0m[0;34m[0m[0m
[0m[1;32m      2[0m [0;32mfrom[0m [0msklearn[0m[0;34m.[0m[0mdatasets[0m [0;32mimport[0m [0mmake_classification[0m[0;34m[0m[0;34m[0m[0m
[1;32m      3[0m [0;32mfrom[0m [0msklearn[0m[0;34m.[0m[0mmetrics[0m [0;32mimport[0m [0mplot_confusion_matrix[0m[0;34m[0m[0;34m[0m[0m
[1;32m      4[0m [0;32mfrom[0m [0msklearn[0m[0;34m.[0m[0mmodel_selection[0m [0;32mimport[0m [0mtrain_test_split[0m[0;34m[0m[0;34m[0m[0m
[1;32m      5[0m [0;32mfrom[0m [0msklearn[0m[0;34m.[0m[0msvm[0m [0;32mimport[0m [0mSVC[0m[0;34m[0m[0;34m[0m[0m

[0;31mModuleNotFoundError[0m: No module named 'matplotlib'
ModuleNotFoundError: No module named 'matplotlib'

